2021-01-17 17:24:15,088 INFO    MainThread:7058 [internal.py:wandb_internal():62] W&B internal server running at pid: 7058
2021-01-17 17:24:15,097 DEBUG   HandlerThread:7058 [handler.py:handle_request():54] handle_request: check_version
2021-01-17 17:24:15,097 INFO    WriterThread:7058 [datastore.py:open_for_write():76] open: wandb/run-20210117_172413-1x8umzak/run-1x8umzak.wandb
2021-01-17 17:24:15,101 DEBUG   SenderThread:7058 [sender.py:send():88] send: header
2021-01-17 17:24:15,101 DEBUG   SenderThread:7058 [sender.py:send():88] send: request
2021-01-17 17:24:15,102 DEBUG   SenderThread:7058 [sender.py:send_request():97] send_request: check_version
2021-01-17 17:24:15,137 DEBUG   Thread-10 :7058 [connectionpool.py:_new_conn():943] Starting new HTTPS connection (1): pypi.org:443
2021-01-17 17:24:15,292 DEBUG   Thread-10 :7058 [connectionpool.py:_make_request():442] https://pypi.org:443 "GET /pypi/wandb/json HTTP/1.1" 200 52801
2021-01-17 17:24:15,340 DEBUG   SenderThread:7058 [sender.py:send():88] send: run
2021-01-17 17:24:15,370 INFO    SenderThread:7058 [sender.py:_maybe_setup_resume():269] checking resume status for None/YOLOv5/1x8umzak
2021-01-17 17:24:15,379 DEBUG   SenderThread:7058 [connectionpool.py:_new_conn():943] Starting new HTTPS connection (1): api.wandb.ai:443
2021-01-17 17:24:15,739 DEBUG   SenderThread:7058 [connectionpool.py:_make_request():442] https://api.wandb.ai:443 "POST /graphql HTTP/1.1" 200 None
2021-01-17 17:24:15,749 DEBUG   SenderThread:7058 [cmd.py:execute():719] Popen(['git', 'cat-file', '--batch-check'], cwd=/media/thang/New Volume/Active-learning-for-object-detection, universal_newlines=False, shell=None, istream=<valid stream>)
2021-01-17 17:24:15,794 DEBUG   SenderThread:7058 [connectionpool.py:_new_conn():943] Starting new HTTPS connection (1): api.wandb.ai:443
2021-01-17 17:24:16,326 DEBUG   SenderThread:7058 [connectionpool.py:_make_request():442] https://api.wandb.ai:443 "POST /graphql HTTP/1.1" 409 None
2021-01-17 17:24:16,329 ERROR   SenderThread:7058 [internal_api.py:execute():131] 409 response executing GraphQL.
2021-01-17 17:24:16,330 ERROR   SenderThread:7058 [internal_api.py:execute():132] {"errors":[{"message":"Error 1062: Duplicate entry '182406-1x8umzak' for key 'PRIMARY'","path":["upsertBucket"]}],"data":{"upsertBucket":null}}
2021-01-17 17:24:17,575 DEBUG   SenderThread:7058 [connectionpool.py:_new_conn():943] Starting new HTTPS connection (1): api.wandb.ai:443
2021-01-17 17:24:18,012 DEBUG   SenderThread:7058 [connectionpool.py:_make_request():442] https://api.wandb.ai:443 "POST /graphql HTTP/1.1" 409 None
2021-01-17 17:24:18,015 ERROR   SenderThread:7058 [internal_api.py:execute():131] 409 response executing GraphQL.
2021-01-17 17:24:18,016 ERROR   SenderThread:7058 [internal_api.py:execute():132] {"errors":[{"message":"Error 1062: Duplicate entry '182406-1x8umzak' for key 'PRIMARY'","path":["upsertBucket"]}],"data":{"upsertBucket":null}}
2021-01-17 17:24:20,110 DEBUG   SenderThread:7058 [connectionpool.py:_new_conn():943] Starting new HTTPS connection (1): api.wandb.ai:443
2021-01-17 17:24:20,572 DEBUG   SenderThread:7058 [connectionpool.py:_make_request():442] https://api.wandb.ai:443 "POST /graphql HTTP/1.1" 409 None
2021-01-17 17:24:20,575 ERROR   SenderThread:7058 [internal_api.py:execute():131] 409 response executing GraphQL.
2021-01-17 17:24:20,575 ERROR   SenderThread:7058 [internal_api.py:execute():132] {"errors":[{"message":"Error 1062: Duplicate entry '182406-1x8umzak' for key 'PRIMARY'","path":["upsertBucket"]}],"data":{"upsertBucket":null}}
2021-01-17 17:24:20,576 ERROR   SenderThread:7058 [retry.py:__call__():111] Retry attempt failed:
Traceback (most recent call last):
  File "/home/thang/env/lib/python3.6/site-packages/wandb/old/retry.py", line 96, in __call__
    result = self._call_fn(*args, **kwargs)
  File "/home/thang/env/lib/python3.6/site-packages/wandb/internal/internal_api.py", line 134, in execute
    six.reraise(*sys.exc_info())
  File "/home/thang/env/lib/python3.6/site-packages/six.py", line 703, in reraise
    raise value
  File "/home/thang/env/lib/python3.6/site-packages/wandb/internal/internal_api.py", line 128, in execute
    return self.client.execute(*args, **kwargs)
  File "/home/thang/env/lib/python3.6/site-packages/wandb/vendor/gql-0.2.0/gql/client.py", line 52, in execute
    result = self._get_result(document, *args, **kwargs)
  File "/home/thang/env/lib/python3.6/site-packages/wandb/vendor/gql-0.2.0/gql/client.py", line 60, in _get_result
    return self.transport.execute(document, *args, **kwargs)
  File "/home/thang/env/lib/python3.6/site-packages/wandb/vendor/gql-0.2.0/gql/transport/requests.py", line 39, in execute
    request.raise_for_status()
  File "/home/thang/env/lib/python3.6/site-packages/requests/models.py", line 941, in raise_for_status
    raise HTTPError(http_error_msg, response=self)
requests.exceptions.HTTPError: 409 Client Error: Conflict for url: https://api.wandb.ai/graphql
2021-01-17 17:24:25,089 DEBUG   SenderThread:7058 [connectionpool.py:_new_conn():943] Starting new HTTPS connection (1): api.wandb.ai:443
2021-01-17 17:24:25,692 DEBUG   SenderThread:7058 [connectionpool.py:_make_request():442] https://api.wandb.ai:443 "POST /graphql HTTP/1.1" 409 None
2021-01-17 17:24:25,695 ERROR   SenderThread:7058 [internal_api.py:execute():131] 409 response executing GraphQL.
2021-01-17 17:24:25,695 ERROR   SenderThread:7058 [internal_api.py:execute():132] {"errors":[{"message":"Error 1062: Duplicate entry '182406-1x8umzak' for key 'PRIMARY'","path":["upsertBucket"]}],"data":{"upsertBucket":null}}
2021-01-17 17:24:34,312 DEBUG   SenderThread:7058 [connectionpool.py:_new_conn():943] Starting new HTTPS connection (1): api.wandb.ai:443
2021-01-17 17:24:34,910 DEBUG   SenderThread:7058 [connectionpool.py:_make_request():442] https://api.wandb.ai:443 "POST /graphql HTTP/1.1" 409 None
2021-01-17 17:24:34,917 ERROR   SenderThread:7058 [internal_api.py:execute():131] 409 response executing GraphQL.
2021-01-17 17:24:34,918 ERROR   SenderThread:7058 [internal_api.py:execute():132] {"errors":[{"message":"Error 1062: Duplicate entry '182406-1x8umzak' for key 'PRIMARY'","path":["upsertBucket"]}],"data":{"upsertBucket":null}}
2021-01-17 17:24:45,341 DEBUG   HandlerThread:7058 [handler.py:handle_request():54] handle_request: shutdown
2021-01-17 17:24:45,343 INFO    HandlerThread:7058 [handler.py:finish():267] shutting down handler
2021-01-17 17:24:45,347 INFO    WriterThread:7058 [datastore.py:close():257] close: wandb/run-20210117_172413-1x8umzak/run-1x8umzak.wandb
2021-01-17 17:24:52,449 DEBUG   SenderThread:7058 [connectionpool.py:_new_conn():943] Starting new HTTPS connection (1): api.wandb.ai:443
2021-01-17 17:24:53,034 DEBUG   SenderThread:7058 [connectionpool.py:_make_request():442] https://api.wandb.ai:443 "POST /graphql HTTP/1.1" 409 None
2021-01-17 17:24:53,042 ERROR   SenderThread:7058 [internal_api.py:execute():131] 409 response executing GraphQL.
2021-01-17 17:24:53,044 ERROR   SenderThread:7058 [internal_api.py:execute():132] {"errors":[{"message":"Error 1062: Duplicate entry '182406-1x8umzak' for key 'PRIMARY'","path":["upsertBucket"]}],"data":{"upsertBucket":null}}
2021-01-17 17:25:28,453 DEBUG   SenderThread:7058 [connectionpool.py:_new_conn():943] Starting new HTTPS connection (1): api.wandb.ai:443
2021-01-17 17:25:28,898 DEBUG   SenderThread:7058 [connectionpool.py:_make_request():442] https://api.wandb.ai:443 "POST /graphql HTTP/1.1" 409 None
2021-01-17 17:25:28,900 ERROR   SenderThread:7058 [internal_api.py:execute():131] 409 response executing GraphQL.
2021-01-17 17:25:28,900 ERROR   SenderThread:7058 [internal_api.py:execute():132] {"errors":[{"message":"Error 1062: Duplicate entry '182406-1x8umzak' for key 'PRIMARY'","path":["upsertBucket"]}],"data":{"upsertBucket":null}}
2021-01-17 17:26:44,002 DEBUG   SenderThread:7058 [connectionpool.py:_new_conn():943] Starting new HTTPS connection (1): api.wandb.ai:443
2021-01-17 17:26:44,482 DEBUG   SenderThread:7058 [connectionpool.py:_make_request():442] https://api.wandb.ai:443 "POST /graphql HTTP/1.1" 409 None
2021-01-17 17:26:44,488 ERROR   SenderThread:7058 [internal_api.py:execute():131] 409 response executing GraphQL.
2021-01-17 17:26:44,503 ERROR   SenderThread:7058 [internal_api.py:execute():132] {"errors":[{"message":"Error 1062: Duplicate entry '182406-1x8umzak' for key 'PRIMARY'","path":["upsertBucket"]}],"data":{"upsertBucket":null}}
2021-01-17 17:28:59,504 DEBUG   SenderThread:7058 [connectionpool.py:_new_conn():943] Starting new HTTPS connection (1): api.wandb.ai:443
2021-01-17 17:29:00,045 DEBUG   SenderThread:7058 [connectionpool.py:_make_request():442] https://api.wandb.ai:443 "POST /graphql HTTP/1.1" 409 None
2021-01-17 17:29:00,071 ERROR   SenderThread:7058 [internal_api.py:execute():131] 409 response executing GraphQL.
2021-01-17 17:29:00,073 ERROR   SenderThread:7058 [internal_api.py:execute():132] {"errors":[{"message":"Error 1062: Duplicate entry '182406-1x8umzak' for key 'PRIMARY'","path":["upsertBucket"]}],"data":{"upsertBucket":null}}
