2021-01-17 17:37:52,589 INFO    MainThread:8116 [internal.py:wandb_internal():62] W&B internal server running at pid: 8116
2021-01-17 17:37:52,607 DEBUG   HandlerThread:8116 [handler.py:handle_request():54] handle_request: check_version
2021-01-17 17:37:52,608 INFO    WriterThread:8116 [datastore.py:open_for_write():76] open: wandb/run-20210117_173750-1x8umzak/run-1x8umzak.wandb
2021-01-17 17:37:52,626 DEBUG   SenderThread:8116 [sender.py:send():88] send: header
2021-01-17 17:37:52,630 DEBUG   SenderThread:8116 [sender.py:send():88] send: request
2021-01-17 17:37:52,631 DEBUG   SenderThread:8116 [sender.py:send_request():97] send_request: check_version
2021-01-17 17:37:52,667 DEBUG   Thread-10 :8116 [connectionpool.py:_new_conn():943] Starting new HTTPS connection (1): pypi.org:443
2021-01-17 17:37:52,899 DEBUG   Thread-10 :8116 [connectionpool.py:_make_request():442] https://pypi.org:443 "GET /pypi/wandb/json HTTP/1.1" 200 52801
2021-01-17 17:37:52,967 DEBUG   SenderThread:8116 [sender.py:send():88] send: run
2021-01-17 17:37:53,003 INFO    SenderThread:8116 [sender.py:_maybe_setup_resume():269] checking resume status for None/YOLOv5/1x8umzak
2021-01-17 17:37:53,012 DEBUG   SenderThread:8116 [connectionpool.py:_new_conn():943] Starting new HTTPS connection (1): api.wandb.ai:443
2021-01-17 17:37:53,391 DEBUG   SenderThread:8116 [connectionpool.py:_make_request():442] https://api.wandb.ai:443 "POST /graphql HTTP/1.1" 200 None
2021-01-17 17:37:53,399 DEBUG   SenderThread:8116 [cmd.py:execute():719] Popen(['git', 'cat-file', '--batch-check'], cwd=/media/thang/New Volume/Active-learning-for-object-detection, universal_newlines=False, shell=None, istream=<valid stream>)
2021-01-17 17:37:53,421 DEBUG   SenderThread:8116 [connectionpool.py:_new_conn():943] Starting new HTTPS connection (1): api.wandb.ai:443
2021-01-17 17:37:53,829 DEBUG   SenderThread:8116 [connectionpool.py:_make_request():442] https://api.wandb.ai:443 "POST /graphql HTTP/1.1" 409 None
2021-01-17 17:37:53,837 ERROR   SenderThread:8116 [internal_api.py:execute():131] 409 response executing GraphQL.
2021-01-17 17:37:53,839 ERROR   SenderThread:8116 [internal_api.py:execute():132] {"errors":[{"message":"Error 1062: Duplicate entry '182406-1x8umzak' for key 'PRIMARY'","path":["upsertBucket"]}],"data":{"upsertBucket":null}}
2021-01-17 17:37:54,989 DEBUG   SenderThread:8116 [connectionpool.py:_new_conn():943] Starting new HTTPS connection (1): api.wandb.ai:443
2021-01-17 17:37:55,467 DEBUG   SenderThread:8116 [connectionpool.py:_make_request():442] https://api.wandb.ai:443 "POST /graphql HTTP/1.1" 409 None
2021-01-17 17:37:55,474 ERROR   SenderThread:8116 [internal_api.py:execute():131] 409 response executing GraphQL.
2021-01-17 17:37:55,476 ERROR   SenderThread:8116 [internal_api.py:execute():132] {"errors":[{"message":"Error 1062: Duplicate entry '182406-1x8umzak' for key 'PRIMARY'","path":["upsertBucket"]}],"data":{"upsertBucket":null}}
2021-01-17 17:37:57,841 DEBUG   SenderThread:8116 [connectionpool.py:_new_conn():943] Starting new HTTPS connection (1): api.wandb.ai:443
2021-01-17 17:37:58,230 DEBUG   SenderThread:8116 [connectionpool.py:_make_request():442] https://api.wandb.ai:443 "POST /graphql HTTP/1.1" 409 None
2021-01-17 17:37:58,232 ERROR   SenderThread:8116 [internal_api.py:execute():131] 409 response executing GraphQL.
2021-01-17 17:37:58,233 ERROR   SenderThread:8116 [internal_api.py:execute():132] {"errors":[{"message":"Error 1062: Duplicate entry '182406-1x8umzak' for key 'PRIMARY'","path":["upsertBucket"]}],"data":{"upsertBucket":null}}
2021-01-17 17:37:58,233 ERROR   SenderThread:8116 [retry.py:__call__():111] Retry attempt failed:
Traceback (most recent call last):
  File "/home/thang/env/lib/python3.6/site-packages/wandb/old/retry.py", line 96, in __call__
    result = self._call_fn(*args, **kwargs)
  File "/home/thang/env/lib/python3.6/site-packages/wandb/internal/internal_api.py", line 134, in execute
    six.reraise(*sys.exc_info())
  File "/home/thang/env/lib/python3.6/site-packages/six.py", line 703, in reraise
    raise value
  File "/home/thang/env/lib/python3.6/site-packages/wandb/internal/internal_api.py", line 128, in execute
    return self.client.execute(*args, **kwargs)
  File "/home/thang/env/lib/python3.6/site-packages/wandb/vendor/gql-0.2.0/gql/client.py", line 52, in execute
    result = self._get_result(document, *args, **kwargs)
  File "/home/thang/env/lib/python3.6/site-packages/wandb/vendor/gql-0.2.0/gql/client.py", line 60, in _get_result
    return self.transport.execute(document, *args, **kwargs)
  File "/home/thang/env/lib/python3.6/site-packages/wandb/vendor/gql-0.2.0/gql/transport/requests.py", line 39, in execute
    request.raise_for_status()
  File "/home/thang/env/lib/python3.6/site-packages/requests/models.py", line 941, in raise_for_status
    raise HTTPError(http_error_msg, response=self)
requests.exceptions.HTTPError: 409 Client Error: Conflict for url: https://api.wandb.ai/graphql
